<mujoco model="left_leg">
  <option gravity="0 0 -9.81" />
  <compiler angle="degree" meshdir="meshes/"/>
  <option timestep="0.001"></option>
  <statistic extent="0.3" center="0.3 0 0" meansize=".03" />
  <asset>
    <mesh name="Left_Hip_Pitch_1" file="Left_Hip_Pitch_1.stl" scale="0.001 0.001 0.001"/>
    <mesh name="Left_Link2_Hip_1" file="Left_Link2_Hip_1.stl" scale="0.001 0.001 0.001"/>
    <mesh name="Left_Thigh_1" file="Left_Thigh_1.stl" scale="0.001 0.001 0.001"/>
    <mesh name="Left_Shank_1" file="Left_Shank_1.stl" scale="0.001 0.001 0.001"/>
    <mesh name="Left_Ankle_Roll_1" file="Left_Ankle_Roll_1.stl" scale="0.001 0.001 0.001"/>
    <mesh name="Left_Foot_1" file="Left_Foot_1.stl" scale="0.001 0.001 0.001"/>
  </asset>
  <default>
    <default class="AK8064_actuator">
        <joint damping="0.02" armature="0.231" frictionloss="4.8" />
    </default>

    <default class="AK7010_actuator">
        <joint damping="0.015" armature="0.00414" frictionloss="0.5" />
    </default>

    <default class="AK109_actuator">
        <joint damping="0.03" armature="0.00812" frictionloss="0.5" />
    </default>

    <default class="AK606_actuator">
        <joint damping="0.02" armature="0.00088" frictionloss="0.25" />
    </default>
</default>
  <visual>
        <headlight diffuse="0.6 0.6 0.6" ambient="0.3 0.3 0.3" specular="0 0 0" />
        <rgba haze="0.15 0.25 0.35 1" />
        <global azimuth="-130" elevation="-20" />
  </visual>

    <asset>
        <texture builtin="gradient" height="100" rgb1=".4 .5 .6" rgb2="0 0 0" type="skybox" width="100" />
        <texture name="texplane" type="2d" builtin="checker" rgb1=".2 .3 .4" rgb2=".1 0.15 0.2" width="100" height="100" />
        <material name="MatPlane" reflectance="0.1" texture="texplane" texrepeat="1 1" texuniform="true" />
    </asset>
  <worldbody>
  <geom name="ground" pos="0 0 0" size="5 5 0.05" type="plane" material = "MatPlane" friction= "1 1 0.1" condim="3" conaffinity="1" contype="1" group="2" rgba="0.8 0.9 0.8 1" />
  <light cutoff="1000" diffuse="1 1 1" dir="-0 0 -1.3" directional="true" exponent="1" pos="0 0 1.3" specular=".1 .1 .1" castshadow="false" />
    <body name="Left_Hip_Pitch_1" pos="0 0.089761 0.8">
      <inertial pos="0.005535 0.05735 -0.014768" quat="0.600093 0.396533 -0.46252 0.518387" mass="1.76429" diaginertia="0.00348932 0.0033391 0.00226458"/>
      <joint name="left_hip_pitch" pos="0 0 0" axis="0 1 0" range="-80 80" actuatorfrcrange="-48 48" />
      <geom pos="0 -0.089761 0.081437" quat="1 0 0 0" type="mesh" contype="0" conaffinity="0" group="1" density="0" mesh="Left_Hip_Pitch_1"/>
      <body name="Left_Link2_Hip_1" pos="0.0445 0.072444 -0.019412">
        <inertial pos="-0.044636 -1.6e-05 -0.073241" quat="0.707529 -0.000179264 0.00188002 0.706682" mass="1.2918" diaginertia="0.00315201 0.002359 0.00197499"/>
        <joint name="left_hip_roll" pos="0 0 0" axis="1 0 0" range="-15 60" actuatorfrcrange="-48 48"/>
        <geom pos="-0.0445 -0.162205 0.100849" quat="1 0 0 0" type="mesh" contype="0" conaffinity="0" group="1" density="0" mesh="Left_Link2_Hip_1"/>
        <body name="Left_Thigh_1" pos="-0.0445 0 -0.1205">
          <inertial pos="-0.000314 -0.013334 -0.166035" quat="0.726022 -0.0341238 0.0343949 0.685963" mass="1.86739" diaginertia="0.012177 0.0116484 0.00198957"/>
          <joint name="left_hip_yaw" pos="0 0 0" axis="0 0 -1" range="-40 40" actuatorfrcrange="-16 16"/>
          <geom pos="0 -0.162205 0.221349" quat="1 0 0 0" type="mesh" contype="0" conaffinity="0" group="1" density="0" mesh="Left_Thigh_1"/>
          <body name="Left_Shank_1" pos="0 0.017 -0.2035">
            <inertial pos="0.0097 -0.013414 -0.163789" quat="0.997974 -0.0278253 -0.0288337 -0.0494257" mass="1.89423" diaginertia="0.0168582 0.0166804 0.00141145"/>
            <joint name="left_knee" pos="0 0 0" axis="0 1 0" range="-5 120" actuatorfrcrange="-48 48"/>
            <geom pos="0 -0.179205 0.424849" quat="1 0 0 0" type="mesh" contype="0" conaffinity="0" group="1" density="0" mesh="Left_Shank_1"/>
            <body name="Left_Ankle_Roll_1" pos="0.019 -0.017 -0.335">
              <inertial pos="-0.019 0 0" quat="0 0.707107 0 0.707107" mass="0.040313" diaginertia="7.00901e-06 5.12501e-06 3.4981e-06"/>
              <joint name="left_ankle_roll" pos="0 0 0" axis="-1 0 0" range="-20 20" actuatorfrcrange="-18 18"/>
              <geom pos="-0.019 -0.162205 0.759849" quat="1 0 0 0" type="mesh" contype="0" conaffinity="0" group="1" density="0" mesh="Left_Ankle_Roll_1"/>
              <body name="Left_Foot_1" pos="-0.019 -0.015 0">
                <inertial pos="0.032254 0.0151022 -0.0319141" quat="0.000188682 0.729142 0.000213619 0.684362" mass="0.343229" diaginertia="0.000946586 0.000877 0.000151414"/>
                <joint name="left_ankle_pitch" pos="0 0 0" axis="0 1 0" range="-30 30" actuatorfrcrange="-18 18"/>
                <geom pos="0 -0.147205 0.759849" quat="1 0 0 0" type="mesh" contype="0" conaffinity="0" group="1" density="0" mesh="Left_Foot_1"/>
              </body>
            </body>
          </body>
        </body>
      </body>
    </body>
  </worldbody>

    <actuator>
        <motor name="left_hip_pitch_m" joint="left_hip_pitch" ctrlrange="-48 48" />
        <motor name="left_hip_roll_m" joint="left_hip_roll" ctrlrange="-48 48" />
        <motor name="left_hip_yaw_m" joint="left_hip_yaw" ctrlrange="-16 16" />
        <motor name="left_knee_m" joint="left_knee" ctrlrange="-48 48" />
        <motor name="left_ankle_roll_m" joint="left_ankle_roll" ctrlrange="-18 18" />
        <motor name="left_ankle_pitch_m" joint="left_ankle_pitch" ctrlrange="-18 18" /> 
    </actuator>
</mujoco>
